<?xml version="1.0"?>
<sdf version="1.10">
    <world name="car_world">
        <physics name="1ms" type="ignored">
            <max_step_size>0.001</max_step_size>
            <real_time_factor>1.0</real_time_factor>
        </physics>
        <plugin
            filename="gz-sim-physics-system"
            name="gz::sim::systems::Physics">
        </plugin>
        <plugin
            filename="gz-sim-user-commands-system"
            name="gz::sim::systems::UserCommands">
        </plugin>
        <plugin
            filename="gz-sim-scene-broadcaster-system"
            name="gz::sim::systems::SceneBroadcaster">
        </plugin>
        <plugin
            filename="gz-sim-imu-system"
            name="gz::sim::systems::Imu">
        </plugin>
        <plugin
            filename="gz-sim-sensors-system"
            name="gz::sim::systems::Sensors">
            <render_engine>ogre2</render_engine>
        </plugin>

        <light type="directional" name="sun">
            <cast_shadows>true</cast_shadows>
            <pose>0 0 10 0 0 0</pose>
            <diffuse>0.8 0.8 0.8 1</diffuse>
            <specular>0.2 0.2 0.2 1</specular>
            <attenuation>
                <range>1000</range>
                <constant>0.9</constant>
                <linear>0.01</linear>
                <quadratic>0.001</quadratic>
            </attenuation>
            <direction>-0.5 0.1 -0.9</direction>
        </light>

        <model name="ground_plane">
            <static>true</static>
            <link name="link">
                <collision name="collision">
                    <geometry>
                        <plane>
                            <normal>0 0 1</normal>
                        </plane>
                    </geometry>
                </collision>
                <visual name="visual">
                    <geometry>
                        <plane>
                            <normal>0 0 1</normal>
                            <size>100 100</size>
                        </plane>
                    </geometry>
                    <material>
                        <ambient>0.8 0.8 0.8 1</ambient>
                        <diffuse>0.8 0.8 0.8 1</diffuse>
                        <specular>0.8 0.8 0.8 1</specular>
                    </material>
                </visual>
            </link>
        </model>

        <model name='wall_north'>
            <static>true</static>
            <pose>10 0 1 0 0 0</pose>
            <link name='box'>
                <visual name='visual'>
                    <geometry>
                        <box>
                            <size>0.5 20.0 2.0</size>
                        </box>
                    </geometry>
                    <material>
                        <ambient>0.5 0.5 0.5 1</ambient>
                        <diffuse>0.5 0.5 0.5 1</diffuse>
                        <specular>0.5 0.5 0.5 1</specular>
                    </material>
                </visual>
                <collision name='collision'>
                    <geometry>
                        <box>
                            <size>0.5 20.0 2.0</size>
                        </box>
                    </geometry>
                </collision>
            </link>
        </model>

        <model name='wall_south'>
            <static>true</static>
            <pose>-10 0 1 0 0 0</pose>
            <link name='box'>
                <visual name='visual'>
                    <geometry>
                        <box>
                            <size>0.5 20.0 2.0</size>
                        </box>
                    </geometry>
                    <material>
                        <ambient>0.5 0.5 0.5 1</ambient>
                        <diffuse>0.5 0.5 0.5 1</diffuse>
                        <specular>0.5 0.5 0.5 1</specular>
                    </material>
                </visual>
                <collision name='collision'>
                    <geometry>
                        <box>
                            <size>0.5 20.0 2.0</size>
                        </box>
                    </geometry>
                </collision>
            </link>
        </model>

        <model name='wall_east'>
            <static>true</static>
            <pose>0 10 1 0 0 1.5707</pose>
            <link name='box'>
                <visual name='visual'>
                    <geometry>
                        <box>
                            <size>0.5 20.0 2.0</size>
                        </box>
                    </geometry>
                    <material>
                        <ambient>0.5 0.5 0.5 1</ambient>
                        <diffuse>0.5 0.5 0.5 1</diffuse>
                        <specular>0.5 0.5 0.5 1</specular>
                    </material>
                </visual>
                <collision name='collision'>
                    <geometry>
                        <box>
                            <size>0.5 20.0 2.0</size>
                        </box>
                    </geometry>
                </collision>
            </link>
        </model>

        <model name='wall_west'>
            <static>true</static>
            <pose>0 -10 1 0 0 1.5707</pose>
            <link name='box'>
                <visual name='visual'>
                    <geometry>
                        <box>
                            <size>0.5 20.0 2.0</size>
                        </box>
                    </geometry>
                    <material>
                        <ambient>0.5 0.5 0.5 1</ambient>
                        <diffuse>0.5 0.5 0.5 1</diffuse>
                        <specular>0.5 0.5 0.5 1</specular>
                    </material>
                </visual>
                <collision name='collision'>
                    <geometry>
                        <box>
                            <size>0.5 20.0 2.0</size>
                        </box>
                    </geometry>
                </collision>
            </link>
        </model>

        <!-- Cylinders -->
        <model name='cylinder_obstacle_1'>
            <static>true</static>
            <pose>5 5 0.5 0 0 0</pose>
            <link name='cylinder'>
                <visual name='visual'>
                    <geometry>
                        <cylinder>
                            <radius>0.5</radius>
                            <length>1.0</length>
                        </cylinder>
                    </geometry>
                    <material>
                        <ambient>0.0 1.0 0.0 1</ambient>
                        <diffuse>0.0 1.0 0.0 1</diffuse>
                        <specular>0.0 1.0 0.0 1</specular>
                    </material>
                </visual>
                <collision name='collision'>
                    <geometry>
                        <cylinder>
                            <radius>0.5</radius>
                            <length>1.0</length>
                        </cylinder>
                    </geometry>
                </collision>
            </link>
        </model>

        <model name='cylinder_obstacle_2'>
            <static>true</static>
            <pose>-5 8 0.5 0 0 0</pose>
            <link name='cylinder'>
                <visual name='visual'>
                    <geometry>
                        <cylinder>
                            <radius>0.5</radius>
                            <length>1.0</length>
                        </cylinder>
                    </geometry>
                    <material>
                        <ambient>0.0 1.0 0.0 1</ambient>
                        <diffuse>0.0 1.0 0.0 1</diffuse>
                        <specular>0.0 1.0 0.0 1</specular>
                    </material>
                </visual>
                <collision name='collision'>
                    <geometry>
                        <cylinder>
                            <radius>0.5</radius>
                            <length>1.0</length>
                        </cylinder>
                    </geometry>
                </collision>
            </link>
        </model>

        <model name='cylinder_obstacle_3'>
            <static>true</static>
            <pose>8 -5 0.5 0 0 0</pose>
            <link name='cylinder'>
                <visual name='visual'>
                    <geometry>
                        <cylinder>
                            <radius>0.5</radius>
                            <length>1.0</length>
                        </cylinder>
                    </geometry>
                    <material>
                        <ambient>0.0 1.0 0.0 1</ambient>
                        <diffuse>0.0 1.0 0.0 1</diffuse>
                        <specular>0.0 1.0 0.0 1</specular>
                    </material>
                </visual>
                <collision name='collision'>
                    <geometry>
                        <cylinder>
                            <radius>0.5</radius>
                            <length>1.0</length>
                        </cylinder>
                    </geometry>
                </collision>
            </link>
        </model>

        <!-- Rectangular Pillars -->
        <model name='box_obstacle_1'>
            <static>true</static>
            <pose>-5 -5 0.5 0 0 0</pose>
            <link name='box'>
                <visual name='visual'>
                    <geometry>
                        <box>
                            <size>1.0 1.0 1.0</size>
                        </box>
                    </geometry>
                    <material>
                        <ambient>1.0 0.0 0.0 1</ambient>
                        <diffuse>1.0 0.0 0.0 1</diffuse>
                        <specular>1.0 0.0 0.0 1</specular>
                    </material>
                </visual>
                <collision name='collision'>
                    <geometry>
                        <box>
                            <size>1.0 1.0 1.0</size>
                        </box>
                    </geometry>
                </collision>
            </link>
        </model>

        <model name='box_obstacle_2'>
            <static>true</static>
            <pose>5 -8 0.5 0 0 0</pose>
            <link name='box'>
                <visual name='visual'>
                    <geometry>
                        <box>
                            <size>1.0 1.0 1.0</size>
                        </box>
                    </geometry>
                    <material>
                        <ambient>1.0 0.0 0.0 1</ambient>
                        <diffuse>1.0 0.0 0.0 1</diffuse>
                        <specular>1.0 0.0 0.0 1</specular>
                    </material>
                </visual>
                <collision name='collision'>
                    <geometry>
                        <box>
                            <size>1.0 1.0 1.0</size>
                        </box>
                    </geometry>
                </collision>
            </link>
        </model>

        <model name='box_obstacle_3'>
            <static>true</static>
            <pose>-8 5 0.5 0 0 0</pose>
            <link name='box'>
                <visual name='visual'>
                    <geometry>
                        <box>
                            <size>1.0 1.0 1.0</size>
                        </box>
                    </geometry>
                    <material>
                        <ambient>1.0 0.0 0.0 1</ambient>
                        <diffuse>1.0 0.0 0.0 1</diffuse>
                        <specular>1.0 0.0 0.0 1</specular>
                    </material>
                </visual>
                <collision name='collision'>
                    <geometry>
                        <box>
                            <size>1.0 1.0 1.0</size>
                        </box>
                    </geometry>
                </collision>
            </link>
        </model>

        <!-- Internal Walls -->
        <model name='internal_wall_1'>
            <static>true</static>
            <pose>0 6 0.5 0 0 0.785</pose>
            <link name='box'>
                <visual name='visual'>
                    <geometry>
                        <box>
                            <size>0.2 4.0 1.0</size>
                        </box>
                    </geometry>
                    <material>
                        <ambient>0.0 0.0 1.0 1</ambient>
                        <diffuse>0.0 0.0 1.0 1</diffuse>
                        <specular>0.0 0.0 1.0 1</specular>
                    </material>
                </visual>
                <collision name='collision'>
                    <geometry>
                        <box>
                            <size>0.2 4.0 1.0</size>
                        </box>
                    </geometry>
                </collision>
            </link>
        </model>

        <model name='internal_wall_2'>
            <static>true</static>
            <pose>6 0 0.5 0 0 0</pose>
            <link name='box'>
                <visual name='visual'>
                    <geometry>
                        <box>
                            <size>0.2 4.0 1.0</size>
                        </box>
                    </geometry>
                    <material>
                        <ambient>0.0 0.0 1.0 1</ambient>
                        <diffuse>0.0 0.0 1.0 1</diffuse>
                        <specular>0.0 0.0 1.0 1</specular>
                    </material>
                </visual>
                <collision name='collision'>
                    <geometry>
                        <box>
                            <size>0.2 4.0 1.0</size>
                        </box>
                    </geometry>
                </collision>
            </link>
        </model>

        <model name='internal_wall_3'>
            <static>true</static>
            <pose>-6 -6 0.5 0 0 -0.785</pose>
            <link name='box'>
                <visual name='visual'>
                    <geometry>
                        <box>
                            <size>0.2 4.0 1.0</size>
                        </box>
                    </geometry>
                    <material>
                        <ambient>0.0 0.0 1.0 1</ambient>
                        <diffuse>0.0 0.0 1.0 1</diffuse>
                        <specular>0.0 0.0 1.0 1</specular>
                    </material>
                </visual>
                <collision name='collision'>
                    <geometry>
                        <box>
                            <size>0.2 4.0 1.0</size>
                        </box>
                    </geometry>
                </collision>
            </link>
        </model>

        <model name='vehicle_blue' canonical_link='base_footprint'>
            <pose>0 0 0 0 0 0</pose>

            <link name='base_footprint'>
                <pose relative_to='__model__'>0 0 0 0 0 0</pose>
                <inertial>
                    <mass>0.0001</mass>
                    <inertia>
                        <ixx>0.0001</ixx>
                        <ixy>0</ixy>
                        <ixz>0</ixz>
                        <iyy>0.0001</iyy>
                        <iyz>0</iyz>
                        <izz>0.0001</izz>
                    </inertia>
                </inertial>
            </link>

            <joint name='base_joint' type='fixed'>
                <parent>base_footprint</parent>
                <child>base_link</child>
            </joint>

            <link name='base_link'>
                <pose relative_to='base_footprint'>0 0 0.15 0 0 0</pose>
                <inertial> <!--inertial
                    properties of the link mass, inertia matix-->
                    <mass>2.2879</mass>
                    <inertia>
                        <ixx>0.095329</ixx>
                        <ixy>0</ixy>
                        <ixz>0</ixz>
                        <iyy>0.381317</iyy>
                        <iyz>0</iyz>
                        <izz>0.476646</izz>
                    </inertia>
                </inertial>
                <visual name='visual'>
                    <geometry>
                        <box>
                            <size>1.0 0.6 0.1</size>
                        </box>
                    </geometry>
                    <!--let's
                    add color to our link-->
                    <material>
                        <ambient>0.0 0.0 1.0 1</ambient>
                        <diffuse>0.0 0.0 1.0 1</diffuse>
                        <specular>0.0 0.0 1.0 1</specular>
                    </material>
                </visual>
                <collision name='collision'>
                    <geometry>
                        <box>
                            <size>1.0 0.6 0.1</size>
                        </box>
                    </geometry>
                </collision>
                <sensor name="imu_sensor" type="imu">
                    <always_on>1</always_on>
                    <update_rate>100</update_rate>
                    <visualize>true</visualize>
                    <topic>imu</topic>
                    <imu>
                        <angular_velocity>
                            <x>
                                <noise type="gaussian">
                                    <mean>0.0</mean>
                                    <stddev>2e-4</stddev>
                                </noise>
                            </x>
                            <y>
                                <noise type="gaussian">
                                    <mean>0.0</mean>
                                    <stddev>2e-4</stddev>
                                </noise>
                            </y>
                            <z>
                                <noise type="gaussian">
                                    <mean>0.0</mean>
                                    <stddev>2e-4</stddev>
                                </noise>
                            </z>
                        </angular_velocity>
                        <linear_acceleration>
                            <x>
                                <noise type="gaussian">
                                    <mean>0.0</mean>
                                    <stddev>1.7e-2</stddev>
                                </noise>
                            </x>
                            <y>
                                <noise type="gaussian">
                                    <mean>0.0</mean>
                                    <stddev>1.7e-2</stddev>
                                </noise>
                            </y>
                            <z>
                                <noise type="gaussian">
                                    <mean>0.0</mean>
                                    <stddev>1.7e-2</stddev>
                                </noise>
                            </z>
                        </linear_acceleration>
                    </imu>
                </sensor>
            </link>

            <link name='left_wheel'>
                <pose relative_to="base_link">0 0.25 -0.075 -1.5707 0 0</pose>
                <inertial>
                    <mass>1</mass>
                    <inertia>
                        <ixx>0.043333</ixx>
                        <ixy>0</ixy>
                        <ixz>0</ixz>
                        <iyy>0.043333</iyy>
                        <iyz>0</iyz>
                        <izz>0.08</izz>
                    </inertia>
                </inertial>
                <visual name='visual'>
                    <geometry>
                        <cylinder>
                            <radius>0.075</radius>
                            <length>0.1</length>
                        </cylinder>
                    </geometry>
                    <material>
                        <ambient>1.0 0.0 0.0 1</ambient>
                        <diffuse>1.0 0.0 0.0 1</diffuse>
                        <specular>1.0 0.0 0.0 1</specular>
                    </material>
                </visual>
                <collision name='collision'>
                    <geometry>
                        <cylinder>
                            <radius>0.075</radius>
                            <length>0.1</length>
                        </cylinder>
                    </geometry>
                </collision>
            </link>

            <link name='right_wheel'>
                <pose relative_to="base_link">0 -0.25 -0.075 -1.5707 0 0</pose>
                <inertial>
                    <mass>1</mass>
                    <inertia>
                        <ixx>0.043333</ixx>
                        <ixy>0</ixy>
                        <ixz>0</ixz>
                        <iyy>0.043333</iyy>
                        <iyz>0</iyz>
                        <izz>0.08</izz>
                    </inertia>
                </inertial>
                <visual name='visual'>
                    <geometry>
                        <cylinder>
                            <radius>0.075</radius>
                            <length>0.1</length>
                        </cylinder>
                    </geometry>
                    <material>
                        <ambient>1.0 0.0 0.0 1</ambient>
                        <diffuse>1.0 0.0 0.0 1</diffuse>
                        <specular>1.0 0.0 0.0 1</specular>
                    </material>
                </visual>
                <collision name='collision'>
                    <geometry>
                        <cylinder>
                            <radius>0.075</radius>
                            <length>0.1</length>
                        </cylinder>
                    </geometry>
                </collision>
            </link>

            <frame name="front_caster_frame" attached_to='base_link'>
                <pose>0.4 0 -0.075 0 0 0</pose>
            </frame>

            <frame name="rear_caster_frame" attached_to='base_link'>
                <pose>-0.4 0 -0.075 0 0 0</pose>
            </frame>

            <frame name="lidar_frame" attached_to='base_link'>
                <pose>0.4 0 0.1 0 0 0</pose>
            </frame>

            <link name='lidar'>
                <pose relative_to='lidar_frame' />
                <inertial>
                    <mass>0.1</mass>
                    <inertia>
                        <ixx>0.000166667</ixx>
                        <ixy>0</ixy>
                        <ixz>0</ixz>
                        <iyy>0.000166667</iyy>
                        <iyz>0</iyz>
                        <izz>0.000166667</izz>
                    </inertia>
                </inertial>
                <visual name='visual'>
                    <geometry>
                        <cylinder>
                            <radius>0.1</radius>
                            <length>0.1</length>
                        </cylinder>
                    </geometry>
                    <material>
                        <ambient>0.0 0.0 0.0 1</ambient>
                        <diffuse>0.0 0.0 0.0 1</diffuse>
                        <specular>0.0 0.0 0.0 1</specular>
                    </material>
                </visual>
                <collision name='collision'>
                    <geometry>
                        <cylinder>
                            <radius>0.1</radius>
                            <length>0.1</length>
                        </cylinder>
                    </geometry>
                </collision>
                <sensor name='gpu_lidar' type='gpu_lidar'>
                    <pose relative_to='lidar_frame'>0 0 0 0 0 0</pose>
                    <topic>lidar</topic>
                    <update_rate>10</update_rate>

                    <ray>
                        <scan>
                            <horizontal>
                                <samples>640</samples>
                                <resolution>1</resolution>
                                <min_angle>-1.396263</min_angle>
                                <max_angle>1.396263</max_angle>
                            </horizontal>
                            <vertical>
                                <samples>1</samples>
                                <resolution>0.01</resolution>
                                <min_angle>0</min_angle>
                                <max_angle>0</max_angle>
                            </vertical>
                        </scan>
                        <range>
                            <min>0.08</min>
                            <max>10.0</max>
                            <resolution>0.01</resolution>
                        </range>
                    </ray>
                    <always_on>1</always_on>
                    <visualize>true</visualize>
                </sensor>
            </link>

            <link name='front_caster'>
                <pose relative_to='front_caster_frame' />
                <inertial>
                    <mass>1</mass>
                    <inertia>
                        <ixx>0.009</ixx>
                        <ixy>0</ixy>
                        <ixz>0</ixz>
                        <iyy>0.009</iyy>
                        <iyz>0</iyz>
                        <izz>0.009</izz>
                    </inertia>
                </inertial>
                <visual name='visual'>
                    <geometry>
                        <sphere>
                            <radius>0.075</radius>
                        </sphere>
                    </geometry>
                    <material>
                        <ambient>0.0 1 0.0 1</ambient>
                        <diffuse>0.0 1 0.0 1</diffuse>
                        <specular>0.0 1 0.0 1</specular>
                    </material>
                </visual>
                <collision name='collision'>
                    <geometry>
                        <sphere>
                            <radius>0.075</radius>
                        </sphere>
                    </geometry>
                </collision>
            </link>

            <link name='rear_caster'>
                <pose relative_to='rear_caster_frame' />
                <inertial>
                    <mass>1</mass>
                    <inertia>
                        <ixx>0.009</ixx>
                        <ixy>0</ixy>
                        <ixz>0</ixz>
                        <iyy>0.009</iyy>
                        <iyz>0</iyz>
                        <izz>0.009</izz>
                    </inertia>
                </inertial>
                <visual name='visual'>
                    <geometry>
                        <sphere>
                            <radius>0.075</radius>
                        </sphere>
                    </geometry>
                    <material>
                        <ambient>0.0 1 0.0 1</ambient>
                        <diffuse>0.0 1 0.0 1</diffuse>
                        <specular>0.0 1 0.0 1</specular>
                    </material>
                </visual>
                <collision name='collision'>
                    <geometry>
                        <sphere>
                            <radius>0.075</radius>
                        </sphere>
                    </geometry>
                </collision>
            </link>

            <joint name='left_wheel_joint' type='revolute'>
                <pose relative_to='left_wheel' />
                <parent>base_link</parent>
                <child>left_wheel</child>
                <axis>
                    <xyz expressed_in='__model__'>0 1 0</xyz>
                    <limit>
                        <lower>-1.79769e+308</lower>    <!--negative
                        infinity-->
                        <upper>1.79769e+308</upper>     <!--positive
                        infinity-->
                    </limit>
                </axis>
            </joint>

            <joint name='right_wheel_joint' type='revolute'>
                <pose relative_to='right_wheel' />
                <parent>base_link</parent>
                <child>right_wheel</child>
                <axis>
                    <xyz expressed_in='__model__'>0 1 0</xyz>
                    <limit>
                        <lower>-1.79769e+308</lower>    <!--negative
                        infinity-->
                        <upper>1.79769e+308</upper>     <!--positive
                        infinity-->
                    </limit>
                </axis>
            </joint>

            <joint name='front_caster_wheel' type='ball'>
                <parent>base_link</parent>
                <child>front_caster</child>
            </joint>

            <joint name='rear_caster_wheel' type='ball'>
                <parent>base_link</parent>
                <child>rear_caster</child>
            </joint>

            <joint name='lidar_joint' type='fixed'>
                <parent>base_link</parent>
                <child>lidar</child>
            </joint>

            <plugin
                filename="gz-sim-diff-drive-system"
                name="gz::sim::systems::DiffDrive">
                <left_joint>left_wheel_joint</left_joint>
                <right_joint>right_wheel_joint</right_joint>
                <wheel_separation>0.5</wheel_separation>
                <wheel_radius>0.075</wheel_radius>
                <odom_publish_frequency>50</odom_publish_frequency>
                <topic>cmd_vel</topic>
                <frame_id>odom</frame_id>
                <child_frame_id>base_footprint</child_frame_id>
            </plugin>
        </model>
    </world>
</sdf>